Python 3.7.0 (v3.7.0:1bf9cc5093, Jun 27 2018, 04:59:51) [MSC v.1914 64 bit (AMD64)] on win32
Type "copyright", "credits" or "license()" for more information.
>>> 
=========== RESTART: C:/Users/Sinchana/Desktop/python prog/tk14.py ===========
python
>>> 
=========== RESTART: C:/Users/Sinchana/Desktop/python prog/tk14.py ===========
ttt
>>> 
=========== RESTART: C:/Users/Sinchana/Desktop/python prog/tk14.py ===========
>>> 
========= RESTART: C:\Users\Sinchana\Desktop\python prog\empclass.py =========
{'first': 'manasa', 'last': 's', 'salary': 50000, 'email_id': 'manasa.s@company.com'}
{'first': 'kushi', 'last': 'd', 'salary': 60000, 'email_id': 'kushi.d@company.com', 'lang': 'pyton', 'desig': 'programmer'}
salary after hike 66000.0
{'first': 'madhu', 'last': 'gn', 'salary': 70000, 'email_id': 'madhu.gn@company.com', 'lang': 'java', 'experience': 5, 'desig': 'testing'}
salary after hike 77000.0
>>> 
========= RESTART: C:\Users\Sinchana\Desktop\python prog\empclass.py =========
Traceback (most recent call last):
  File "C:\Users\Sinchana\Desktop\python prog\empclass.py", line 13, in <module>
    print(emp.__dict__)
AttributeError: 'list' object has no attribute '__dict__'
>>> 
========= RESTART: C:\Users\Sinchana\Desktop\python prog\empclass.py =========
[<__main__.employee object at 0x000000734E40F908>]
>>> 
========= RESTART: C:\Users\Sinchana\Desktop\python prog\empclass.py =========
{0: <__main__.employee object at 0x000000C8F706F9B0>}
>>> 
========= RESTART: C:\Users\Sinchana\Desktop\python prog\empclass.py =========
Traceback (most recent call last):
  File "C:\Users\Sinchana\Desktop\python prog\empclass.py", line 14, in <module>
    print(emp.__dict__)
AttributeError: 'dict' object has no attribute '__dict__'
>>> 
=========== RESTART: C:/Users/Sinchana/Desktop/python prog/tk14.py ===========
ttt
Exception in Tkinter callback
Traceback (most recent call last):
  File "C:\Users\Sinchana\AppData\Local\Programs\Python\Python37\lib\tkinter\__init__.py", line 1702, in __call__
    return self.func(*args)
  File "C:/Users/Sinchana/Desktop/python prog/tk14.py", line 15, in selected
    messagebox.showinfo('hello','number is ',n)
TypeError: showinfo() takes from 0 to 2 positional arguments but 3 were given

=========== RESTART: C:/Users/Sinchana/Desktop/python prog/tk14.py ===========
ttt
Exception in Tkinter callback
Traceback (most recent call last):
  File "C:\Users\Sinchana\AppData\Local\Programs\Python\Python37\lib\tkinter\__init__.py", line 1702, in __call__
    return self.func(*args)
  File "C:/Users/Sinchana/Desktop/python prog/tk14.py", line 15, in selected
    messagebox.showinfo('hello','number is '+n)
TypeError: can only concatenate str (not "int") to str
>>> 
=========== RESTART: C:/Users/Sinchana/Desktop/python prog/tk14.py ===========
ttt
>>> 
= RESTART: C:/Users/Sinchana/Desktop/python prog/front_end_for_fruitshop.py =
Exception in Tkinter callback
Traceback (most recent call last):
  File "C:\Users\Sinchana\AppData\Local\Programs\Python\Python37\lib\tkinter\__init__.py", line 1702, in __call__
    return self.func(*args)
  File "C:/Users/Sinchana/Desktop/python prog/front_end_for_fruitshop.py", line 22, in done1
    n+=1
UnboundLocalError: local variable 'n' referenced before assignment
Exception in Tkinter callback
Traceback (most recent call last):
  File "C:\Users\Sinchana\AppData\Local\Programs\Python\Python37\lib\tkinter\__init__.py", line 1702, in __call__
    return self.func(*args)
  File "C:/Users/Sinchana/Desktop/python prog/front_end_for_fruitshop.py", line 59, in sell
    fruitshop.s3.get().sell(var2.get(),s4.get())
AttributeError: module 'fruitshop' has no attribute 's3'
Exception in Tkinter callback
Traceback (most recent call last):
  File "C:\Users\Sinchana\AppData\Local\Programs\Python\Python37\lib\tkinter\__init__.py", line 1702, in __call__
    return self.func(*args)
  File "C:/Users/Sinchana/Desktop/python prog/front_end_for_fruitshop.py", line 92, in buy
    fruitshop.s5.get().buy(var3.get(),s6.get())
AttributeError: module 'fruitshop' has no attribute 's5'
Exception in Tkinter callback
Traceback (most recent call last):
  File "C:\Users\Sinchana\AppData\Local\Programs\Python\Python37\lib\tkinter\__init__.py", line 1702, in __call__
    return self.func(*args)
  File "C:/Users/Sinchana/Desktop/python prog/front_end_for_fruitshop.py", line 115, in donext
    messagebox.showinfo('stock','no of apples are '+fruitshop.fruit.apple+'\nno of mangoes are '+fruitshop.fruit.mango)
TypeError: can only concatenate str (not "int") to str
Exception in Tkinter callback
Traceback (most recent call last):
  File "C:\Users\Sinchana\AppData\Local\Programs\Python\Python37\lib\tkinter\__init__.py", line 1702, in __call__
    return self.func(*args)
  File "C:/Users/Sinchana/Desktop/python prog/front_end_for_fruitshop.py", line 115, in donext
    messagebox.showinfo('stock','no of apples are '+fruitshop.fruit.apple+'\nno of mangoes are '+fruitshop.fruit.mango)
TypeError: can only concatenate str (not "int") to str
>>> 
